[2024-11-05T22:55:23.388+0000] {taskinstance.py:1159} INFO - Dependencies all met for dep_context=non-requeueable deps ti=<TaskInstance: etl_reddit_pipeline.s3_upload manual__2024-11-05T22:55:19.549793+00:00 [queued]>
[2024-11-05T22:55:23.395+0000] {taskinstance.py:1159} INFO - Dependencies all met for dep_context=requeueable deps ti=<TaskInstance: etl_reddit_pipeline.s3_upload manual__2024-11-05T22:55:19.549793+00:00 [queued]>
[2024-11-05T22:55:23.396+0000] {taskinstance.py:1361} INFO - Starting attempt 1 of 1
[2024-11-05T22:55:23.405+0000] {taskinstance.py:1382} INFO - Executing <Task(PythonOperator): s3_upload> on 2024-11-05 22:55:19.549793+00:00
[2024-11-05T22:55:23.409+0000] {standard_task_runner.py:57} INFO - Started process 94 to run task
[2024-11-05T22:55:23.412+0000] {standard_task_runner.py:84} INFO - Running: ['airflow', 'tasks', 'run', 'etl_reddit_pipeline', 's3_upload', 'manual__2024-11-05T22:55:19.549793+00:00', '--job-id', '13', '--raw', '--subdir', 'DAGS_FOLDER/reddit_dag.py', '--cfg-path', '/tmp/tmp02adgbqk']
[2024-11-05T22:55:23.415+0000] {standard_task_runner.py:85} INFO - Job 13: Subtask s3_upload
[2024-11-05T22:55:23.457+0000] {task_command.py:416} INFO - Running <TaskInstance: etl_reddit_pipeline.s3_upload manual__2024-11-05T22:55:19.549793+00:00 [running]> on host 670f27e5f990
[2024-11-05T22:55:23.508+0000] {taskinstance.py:1662} INFO - Exporting env vars: AIRFLOW_CTX_DAG_OWNER='Bruno Xie' AIRFLOW_CTX_DAG_ID='etl_reddit_pipeline' AIRFLOW_CTX_TASK_ID='s3_upload' AIRFLOW_CTX_EXECUTION_DATE='2024-11-05T22:55:19.549793+00:00' AIRFLOW_CTX_TRY_NUMBER='1' AIRFLOW_CTX_DAG_RUN_ID='manual__2024-11-05T22:55:19.549793+00:00'
[2024-11-05T22:55:23.511+0000] {taskinstance.py:1937} ERROR - Task failed with exception
Traceback (most recent call last):
  File "/home/airflow/.local/lib/python3.9/site-packages/airflow/operators/python.py", line 192, in execute
    return_value = self.execute_callable()
  File "/home/airflow/.local/lib/python3.9/site-packages/airflow/operators/python.py", line 209, in execute_callable
    return self.python_callable(*self.op_args, **self.op_kwargs)
  File "/opt/airflow/pipelines/aws_s3_pipeline.py", line 5, in upload_s3_pipeline
    file_path = ti.xcom_pull(task_id='reddit_extraction', key='return_value')
  File "/home/airflow/.local/lib/python3.9/site-packages/airflow/utils/session.py", line 77, in wrapper
    return func(*args, session=session, **kwargs)
TypeError: xcom_pull() got an unexpected keyword argument 'task_id'
[2024-11-05T22:55:23.520+0000] {taskinstance.py:1400} INFO - Marking task as FAILED. dag_id=etl_reddit_pipeline, task_id=s3_upload, execution_date=20241105T225519, start_date=20241105T225523, end_date=20241105T225523
[2024-11-05T22:55:23.529+0000] {standard_task_runner.py:104} ERROR - Failed to execute job 13 for task s3_upload (xcom_pull() got an unexpected keyword argument 'task_id'; 94)
[2024-11-05T22:55:23.545+0000] {local_task_job_runner.py:228} INFO - Task exited with return code 1
[2024-11-05T22:55:23.558+0000] {taskinstance.py:2778} INFO - 0 downstream tasks scheduled from follow-on schedule check
